#VRML_SIM R2023b utf8
# license: Apache License 2.0
# license url: http://www.apache.org/licenses/LICENSE-2.0
# This is a proto file for Webots for the motor_drive
# Extracted from: /tmp/tmpfhi7tsrq.urdf

PROTO motor_drive [
  field  SFVec3f     translation     0 0 0
  field  SFRotation  rotation        0 0 1 0
  field  SFString    name            "motor_drive"  # Is `Robot.name`.
  field  SFString    controller      "void"         # Is `Robot.controller`.
  field  MFString    controllerArgs  []             # Is `Robot.controllerArgs`.
  field  SFString    customData      ""             # Is `Robot.customData`.
  field  SFBool      supervisor      FALSE          # Is `Robot.supervisor`.
  field  SFBool      synchronization TRUE           # Is `Robot.synchronization`.
  field  SFBool      selfCollision   FALSE          # Is `Robot.selfCollision`.
  field  MFNode      lidarSlot        []
]
{
  Robot {
    translation IS translation
    rotation IS rotation
    controller IS controller
    controllerArgs IS controllerArgs
    customData IS customData
    supervisor IS supervisor
    synchronization IS synchronization
    selfCollision IS selfCollision
    children [
      DEF LIDAR Pose {
        translation 0 0 0.23
        children IS lidarSlot
      }
      Pose {
        translation 0.000000 0.000000 0.140000
        children [
          Shape {
            appearance DEF blue PBRAppearance {
              baseColor 0.500000 0.500000 0.500000
              roughness 1.000000
              metalness 0
            }
            geometry Box {
               size 0.420000 0.310000 0.180000
            }
          }
        ]
      }
      HingeJoint {
        jointParameters HingeJointParameters {
          axis 0.000000 1.000000 0.000000
          anchor -0.120000 0.180000 0.100000
          suspensionSpringConstant 0
          suspensionDampingConstant 0
          suspensionAxis 0 0 1
        }
        device [
          RotationalMotor {
            name "joint_1"
            maxTorque 10000
          }
          PositionSensor {
            name "joint_1_sensor"
          }
        ]
        endPoint Solid {
          translation -0.120000 0.180000 0.100000
          children [
            Pose {
              rotation 1.000000 0.000000 0.000000 1.570796
              children [
                Shape {
                  appearance DEF white PBRAppearance {
                    baseColor 0.500000 0.500000 0.500000
                    roughness 1.000000
                    metalness 0
                  }
                  geometry Cylinder {
                    radius 0.1
                    height 0.04
                  }
                }
              ]
            }
          ]
          name "joint_link_1"
          boundingObject Pose {
            rotation 1.000000 0.000000 0.000000 1.570796
            children [
              Cylinder {
                radius 0.1
                height 0.04
              }
            ]
          }
          physics Physics {
            density -1
            mass 0.500000
            centerOfMass [ 0.000000 0.000000 0.000000 ]
            inertiaMatrix [
              1.316667e-03 2.500000e-03 1.316667e-03
              0.000000e+00 0.000000e+00 7.245827e-20
            ]
          }
        }
      }
      HingeJoint {
        jointParameters HingeJointParameters {
          axis 0.000000 1.000000 0.000000
          anchor -0.120000 -0.180000 0.100000
          suspensionSpringConstant 0
          suspensionDampingConstant 0
          suspensionAxis 0 0 1
        }
        device [
          RotationalMotor {
            name "joint_2"
            maxTorque 10000
          }
          PositionSensor {
            name "joint_2_sensor"
          }
        ]
        endPoint Solid {
          translation -0.120000 -0.180000 0.100000
          children [
            Pose {
              rotation 1.000000 0.000000 0.000000 1.570796
              children [
                Shape {
                  appearance USE white
                  geometry Cylinder {
                    radius 0.1
                    height 0.04
                  }
                }
              ]
            }
          ]
          name "joint_link_2"
          boundingObject Pose {
            rotation 1.000000 0.000000 0.000000 1.570796
            children [
              Cylinder {
                radius 0.1
                height 0.04
              }
            ]
          }
          physics Physics {
            density -1
            mass 0.500000
            centerOfMass [ 0.000000 0.000000 0.000000 ]
            inertiaMatrix [
              1.316667e-03 2.500000e-03 1.316667e-03
              0.000000e+00 0.000000e+00 7.245827e-20
            ]
          }
        }
      }
      Solid {
        translation 0.140000 0.000000 0.025000
        children [
          Shape {
            appearance USE white
            geometry Sphere {
              radius 0.025
            }
          }
        ]
        name "front_caster"
        boundingObject Sphere {
          radius 0.025
        }
        physics Physics {
          density -1
          mass 5.000000
          centerOfMass [ 0.000000 0.000000 0.000000 ]
          inertiaMatrix [
            3.920000e-02 3.920000e-02 3.920000e-02
            0.000000e+00 0.000000e+00 0.000000e+00
          ]
        }
      }
      Solid {
        translation 0.000000 0.000000 0.230000
        children [
          Shape {
            appearance DEF lidar_visual PBRAppearance {
              baseColor 0.800000 0.000000 0.000000
              roughness 1.000000
              metalness 0
            }
            geometry Cylinder {
              radius 0.0508
              height 0.055
            }
          }
        ]
        name "lidar_link"
        boundingObject Cylinder {
          radius 0.0508
          height 0.055
        }
        physics Physics {
          density -1
          mass 0.125000
          centerOfMass [ 0.000000 0.000000 0.000000 ]
          inertiaMatrix [
            1.000000e-03 1.000000e-03 1.000000e-03
            0.000000e+00 0.000000e+00 0.000000e+00
          ]
        }
      }
    ]
    name IS name
    boundingObject Pose {
      translation 0.000000 0.000000 0.140000
      children [
        Box {
           size 0.420000 0.310000 0.180000
        }
      ]
    }
    physics Physics {
      density -1
      mass 15.000000
      centerOfMass [ 0.000000 0.000000 0.000000 ]
      inertiaMatrix [
        3.406250e-01 1.606250e-01 2.610000e-01
        -2.151057e-18 1.129652e-17 -4.454770e-18
      ]
    }
  }
}
